<?xml version="1.0"?>
<robot name="demo_bot" xmlns:xacro="http://www.ros.org/wiki/xacro">
  <xacro:arg name="controllers_file" default=""/>
  <xacro:arg name="use_sim_time" default="true"/>

  <xacro:property name="demo_pi" value="3.1415926535897931"/>
  <xacro:property name="base_length" value="0.40"/>
  <xacro:property name="base_width" value="0.30"/>
  <xacro:property name="base_height" value="0.10"/>
  <xacro:property name="base_mass" value="8.0"/>
  <xacro:property name="wheel_radius" value="0.05"/>
  <xacro:property name="wheel_width" value="0.04"/>
  <xacro:property name="wheel_mass" value="0.6"/>
  <xacro:property name="wheel_y_offset" value="0.17"/>
  <xacro:property name="wheel_z_offset" value="0.05"/>
  <xacro:property name="caster_radius" value="0.03"/>

  <material name="black">
    <color rgba="0.1 0.1 0.1 1.0"/>
  </material>

  <material name="blue">
    <color rgba="0.2 0.4 0.8 1.0"/>
  </material>

  <material name="gray">
    <color rgba="0.7 0.7 0.7 1.0"/>
  </material>

  <xacro:macro name="box_inertia" params="mass x y z">
    <inertial>
      <mass value="${mass}"/>
      <origin xyz="0 0 0" rpy="0 0 0"/>
      <inertia
        ixx="${mass * (y * y + z * z) / 12.0}"
        ixy="0.0"
        ixz="0.0"
        iyy="${mass * (x * x + z * z) / 12.0}"
        iyz="0.0"
        izz="${mass * (x * x + y * y) / 12.0}"/>
    </inertial>
  </xacro:macro>

  <xacro:macro name="cylinder_inertia" params="mass radius length">
    <inertial>
      <mass value="${mass}"/>
      <origin xyz="0 0 0" rpy="0 0 0"/>
      <inertia
        ixx="${mass * (3.0 * radius * radius + length * length) / 12.0}"
        ixy="0.0"
        ixz="0.0"
        iyy="${mass * (3.0 * radius * radius + length * length) / 12.0}"
        iyz="0.0"
        izz="${mass * radius * radius / 2.0}"/>
    </inertial>
  </xacro:macro>

  <xacro:macro name="sphere_inertia" params="mass radius">
    <inertial>
      <mass value="${mass}"/>
      <origin xyz="0 0 0" rpy="0 0 0"/>
      <inertia
        ixx="${2.0 * mass * radius * radius / 5.0}"
        ixy="0.0"
        ixz="0.0"
        iyy="${2.0 * mass * radius * radius / 5.0}"
        iyz="0.0"
        izz="${2.0 * mass * radius * radius / 5.0}"/>
    </inertial>
  </xacro:macro>

  <link name="base_link">
    <visual>
      <origin xyz="0 0 ${base_height / 2.0}" rpy="0 0 0"/>
      <geometry>
        <box size="${base_length} ${base_width} ${base_height}"/>
      </geometry>
      <material name="blue"/>
    </visual>
    <collision>
      <origin xyz="0 0 ${base_height / 2.0}" rpy="0 0 0"/>
      <geometry>
        <box size="${base_length} ${base_width} ${base_height}"/>
      </geometry>
    </collision>
    <xacro:box_inertia mass="${base_mass}" x="${base_length}" y="${base_width}" z="${base_height}"/>
  </link>

  <link name="left_wheel_link">
    <visual>
      <origin xyz="0 0 0" rpy="${demo_pi / 2.0} 0 0"/>
      <geometry>
        <cylinder radius="${wheel_radius}" length="${wheel_width}"/>
      </geometry>
      <material name="black"/>
    </visual>
    <collision>
      <origin xyz="0 0 0" rpy="${demo_pi / 2.0} 0 0"/>
      <geometry>
        <cylinder radius="${wheel_radius}" length="${wheel_width}"/>
      </geometry>
    </collision>
    <xacro:cylinder_inertia mass="${wheel_mass}" radius="${wheel_radius}" length="${wheel_width}"/>
  </link>

  <link name="right_wheel_link">
    <visual>
      <origin xyz="0 0 0" rpy="${demo_pi / 2.0} 0 0"/>
      <geometry>
        <cylinder radius="${wheel_radius}" length="${wheel_width}"/>
      </geometry>
      <material name="black"/>
    </visual>
    <collision>
      <origin xyz="0 0 0" rpy="${demo_pi / 2.0} 0 0"/>
      <geometry>
        <cylinder radius="${wheel_radius}" length="${wheel_width}"/>
      </geometry>
    </collision>
    <xacro:cylinder_inertia mass="${wheel_mass}" radius="${wheel_radius}" length="${wheel_width}"/>
  </link>

  <link name="front_caster_link">
    <visual>
      <origin xyz="0 0 0" rpy="0 0 0"/>
      <geometry>
        <sphere radius="${caster_radius}"/>
      </geometry>
      <material name="gray"/>
    </visual>
    <collision>
      <origin xyz="0 0 0" rpy="0 0 0"/>
      <geometry>
        <sphere radius="${caster_radius}"/>
      </geometry>
    </collision>
    <xacro:sphere_inertia mass="0.2" radius="${caster_radius}"/>
  </link>

  <link name="rear_caster_link">
    <visual>
      <origin xyz="0 0 0" rpy="0 0 0"/>
      <geometry>
        <sphere radius="${caster_radius}"/>
      </geometry>
      <material name="gray"/>
    </visual>
    <collision>
      <origin xyz="0 0 0" rpy="0 0 0"/>
      <geometry>
        <sphere radius="${caster_radius}"/>
      </geometry>
    </collision>
    <xacro:sphere_inertia mass="0.2" radius="${caster_radius}"/>
  </link>

  <joint name="left_wheel_joint" type="continuous">
    <parent link="base_link"/>
    <child link="left_wheel_link"/>
    <origin xyz="0 ${wheel_y_offset} ${wheel_z_offset}" rpy="0 0 0"/>
    <axis xyz="0 1 0"/>
  </joint>

  <joint name="right_wheel_joint" type="continuous">
    <parent link="base_link"/>
    <child link="right_wheel_link"/>
    <origin xyz="0 ${-wheel_y_offset} ${wheel_z_offset}" rpy="0 0 0"/>
    <axis xyz="0 1 0"/>
  </joint>

  <joint name="front_caster_joint" type="fixed">
    <parent link="base_link"/>
    <child link="front_caster_link"/>
    <origin xyz="${base_length / 2.5} 0 ${caster_radius}" rpy="0 0 0"/>
  </joint>

  <joint name="rear_caster_joint" type="fixed">
    <parent link="base_link"/>
    <child link="rear_caster_link"/>
    <origin xyz="${-base_length / 2.5} 0 ${caster_radius}" rpy="0 0 0"/>
  </joint>

  <ros2_control name="GazeboSimSystem" type="system">
    <hardware>
      <plugin>gz_ros2_control/GazeboSimSystem</plugin>
    </hardware>

    <joint name="left_wheel_joint">
      <command_interface name="velocity"/>
      <state_interface name="position"/>
      <state_interface name="velocity"/>
    </joint>

    <joint name="right_wheel_joint">
      <command_interface name="velocity"/>
      <state_interface name="position"/>
      <state_interface name="velocity"/>
    </joint>
  </ros2_control>

  <gazebo>
    <plugin filename="gz_ros2_control-system" name="gz_ros2_control::GazeboSimROS2ControlPlugin">
      <parameters>$(arg controllers_file)</parameters>
    </plugin>
  </gazebo>

  <gazebo reference="left_wheel_link">
    <mu1>1.5</mu1>
    <mu2>1.5</mu2>
  </gazebo>

  <gazebo reference="right_wheel_link">
    <mu1>1.5</mu1>
    <mu2>1.5</mu2>
  </gazebo>
</robot>
